[2020-12-28 15:01:31,842] {taskinstance.py:826} INFO - Dependencies all met for <TaskInstance: foodpanda_crawler.foodpanda_crawler 2020-12-26T01:00:00+00:00 [queued]>
[2020-12-28 15:01:31,860] {taskinstance.py:826} INFO - Dependencies all met for <TaskInstance: foodpanda_crawler.foodpanda_crawler 2020-12-26T01:00:00+00:00 [queued]>
[2020-12-28 15:01:31,860] {taskinstance.py:1017} INFO - 
--------------------------------------------------------------------------------
[2020-12-28 15:01:31,860] {taskinstance.py:1018} INFO - Starting attempt 1 of 1
[2020-12-28 15:01:31,860] {taskinstance.py:1019} INFO - 
--------------------------------------------------------------------------------
[2020-12-28 15:01:31,870] {taskinstance.py:1038} INFO - Executing <Task(DockerOperator): foodpanda_crawler> on 2020-12-26T01:00:00+00:00
[2020-12-28 15:01:31,873] {standard_task_runner.py:51} INFO - Started process 9809 to run task
[2020-12-28 15:01:31,878] {standard_task_runner.py:75} INFO - Running: ['airflow', 'tasks', 'run', 'foodpanda_crawler', 'foodpanda_crawler', '2020-12-26T01:00:00+00:00', '--job-id', '38', '--pool', 'default_pool', '--raw', '--subdir', 'DAGS_FOLDER/foodpanda.py', '--cfg-path', '/tmp/tmp34vt_s5v']
[2020-12-28 15:01:31,879] {standard_task_runner.py:76} INFO - Job 38: Subtask foodpanda_crawler
[2020-12-28 15:01:31,951] {logging_mixin.py:103} INFO - Running <TaskInstance: foodpanda_crawler.foodpanda_crawler 2020-12-26T01:00:00+00:00 [running]> on host dataiku
[2020-12-28 15:01:32,008] {taskinstance.py:1232} INFO - Exporting the following env vars:
AIRFLOW_CTX_DAG_OWNER=arthur.sl.lin
AIRFLOW_CTX_DAG_ID=foodpanda_crawler
AIRFLOW_CTX_TASK_ID=foodpanda_crawler
AIRFLOW_CTX_EXECUTION_DATE=2020-12-26T01:00:00+00:00
AIRFLOW_CTX_DAG_RUN_ID=scheduled__2020-12-26T01:00:00+00:00
[2020-12-28 15:01:32,019] {docker.py:224} INFO - Starting docker container from image arthurtibame/foodpanda_scraper:v2
[2020-12-28 15:01:32,023] {taskinstance.py:1396} ERROR - 409 Client Error: Conflict ("Conflict. The container name "/foodpanda_crawler2020-12-28" is already in use by container "de2488b8129be7bd8f31ca62d79f0c5b264af46d134f1fb2d6466fcf49659cc9". You have to remove (or rename) that container to be able to reuse that name.")
Traceback (most recent call last):
  File "/home/ub/airflow/env/lib/python3.6/site-packages/docker/api/client.py", line 261, in _raise_for_status
    response.raise_for_status()
  File "/home/ub/airflow/env/lib/python3.6/site-packages/requests/models.py", line 941, in raise_for_status
    raise HTTPError(http_error_msg, response=self)
requests.exceptions.HTTPError: 409 Client Error: Conflict for url: http://172.16.16.119:2375/v1.35/containers/create?name=foodpanda_crawler2020-12-28

During handling of the above exception, another exception occurred:

Traceback (most recent call last):
  File "/home/ub/airflow/env/lib/python3.6/site-packages/airflow/models/taskinstance.py", line 1086, in _run_raw_task
    self._prepare_and_execute_task_with_callbacks(context, task)
  File "/home/ub/airflow/env/lib/python3.6/site-packages/airflow/models/taskinstance.py", line 1260, in _prepare_and_execute_task_with_callbacks
    result = self._execute_task(context, task_copy)
  File "/home/ub/airflow/env/lib/python3.6/site-packages/airflow/models/taskinstance.py", line 1300, in _execute_task
    result = task_copy.execute(context=context)
  File "/home/ub/airflow/env/lib/python3.6/site-packages/airflow/providers/docker/operators/docker.py", line 305, in execute
    return self._run_image()
  File "/home/ub/airflow/env/lib/python3.6/site-packages/airflow/providers/docker/operators/docker.py", line 250, in _run_image
    tty=self.tty,
  File "/home/ub/airflow/env/lib/python3.6/site-packages/docker/api/container.py", line 427, in create_container
    return self.create_container_from_config(config, name)
  File "/home/ub/airflow/env/lib/python3.6/site-packages/docker/api/container.py", line 438, in create_container_from_config
    return self._result(res, True)
  File "/home/ub/airflow/env/lib/python3.6/site-packages/docker/api/client.py", line 267, in _result
    self._raise_for_status(response)
  File "/home/ub/airflow/env/lib/python3.6/site-packages/docker/api/client.py", line 263, in _raise_for_status
    raise create_api_error_from_http_exception(e)
  File "/home/ub/airflow/env/lib/python3.6/site-packages/docker/errors.py", line 31, in create_api_error_from_http_exception
    raise cls(e, response=response, explanation=explanation)
docker.errors.APIError: 409 Client Error: Conflict ("Conflict. The container name "/foodpanda_crawler2020-12-28" is already in use by container "de2488b8129be7bd8f31ca62d79f0c5b264af46d134f1fb2d6466fcf49659cc9". You have to remove (or rename) that container to be able to reuse that name.")
[2020-12-28 15:01:32,024] {taskinstance.py:1440} INFO - Marking task as FAILED. dag_id=foodpanda_crawler, task_id=foodpanda_crawler, execution_date=20201226T010000, start_date=20201228T070131, end_date=20201228T070132
[2020-12-28 15:01:32,056] {local_task_job.py:118} INFO - Task exited with return code 1
