[2020-12-25 15:49:45,839] {taskinstance.py:826} INFO - Dependencies all met for <TaskInstance: foodpanda.t1 2020-12-25T07:49:43.118063+00:00 [queued]>
[2020-12-25 15:49:45,843] {taskinstance.py:826} INFO - Dependencies all met for <TaskInstance: foodpanda.t1 2020-12-25T07:49:43.118063+00:00 [queued]>
[2020-12-25 15:49:45,843] {taskinstance.py:1017} INFO - 
--------------------------------------------------------------------------------
[2020-12-25 15:49:45,843] {taskinstance.py:1018} INFO - Starting attempt 1 of 1
[2020-12-25 15:49:45,843] {taskinstance.py:1019} INFO - 
--------------------------------------------------------------------------------
[2020-12-25 15:49:45,850] {taskinstance.py:1038} INFO - Executing <Task(SSHOperator): t1> on 2020-12-25T07:49:43.118063+00:00
[2020-12-25 15:49:45,852] {standard_task_runner.py:51} INFO - Started process 16323 to run task
[2020-12-25 15:49:45,855] {standard_task_runner.py:75} INFO - Running: ['airflow', 'tasks', 'run', 'foodpanda', 't1', '2020-12-25T07:49:43.118063+00:00', '--job-id', '55', '--pool', 'default_pool', '--raw', '--subdir', 'DAGS_FOLDER/ssh_practice.py', '--cfg-path', '/tmp/tmpbvp50z8t']
[2020-12-25 15:49:45,855] {standard_task_runner.py:76} INFO - Job 55: Subtask t1
[2020-12-25 15:49:45,871] {logging_mixin.py:103} INFO - Running <TaskInstance: foodpanda.t1 2020-12-25T07:49:43.118063+00:00 [running]> on host dataiku
[2020-12-25 15:49:45,885] {taskinstance.py:1232} INFO - Exporting the following env vars:
AIRFLOW_CTX_DAG_OWNER=arthur.sl.lin
AIRFLOW_CTX_DAG_ID=foodpanda
AIRFLOW_CTX_TASK_ID=t1
AIRFLOW_CTX_EXECUTION_DATE=2020-12-25T07:49:43.118063+00:00
AIRFLOW_CTX_DAG_RUN_ID=manual__2020-12-25T07:49:43.118063+00:00
[2020-12-25 15:49:45,886] {ssh.py:90} INFO - ssh_hook is not provided or invalid. Trying ssh_conn_id to create SSHHook.
[2020-12-25 15:49:45,888] {base.py:74} INFO - Using connection to: id: crawler_server. Host: 172.16.16.119, Port: 22, Schema: , Login: ub, Password: XXXXXXXX, extra: None
[2020-12-25 15:49:45,888] {ssh.py:197} WARNING - Remote Identification Change is not verified. This wont protect against Man-In-The-Middle attacks
[2020-12-25 15:49:45,889] {ssh.py:202} WARNING - No Host Key Verification. This wont protect against Man-In-The-Middle attacks
[2020-12-25 15:49:45,896] {transport.py:1819} INFO - Connected (version 2.0, client OpenSSH_7.6p1)
[2020-12-25 15:49:45,907] {transport.py:1819} INFO - Authentication (password) successful!
[2020-12-25 15:49:45,907] {ssh.py:109} INFO - Running command: echo "shit airflow
[2020-12-25 15:49:46,037] {ssh.py:141} INFO - bash: -c: line 0: unexpected EOF while looking for matching `"'
bash: -c: line 1: syntax error: unexpected end of file
[2020-12-25 15:49:46,040] {taskinstance.py:1396} ERROR - SSH operator error: error running cmd: echo "shit airflow, error: 
Traceback (most recent call last):
  File "/home/ub/airflow/env/lib/python3.6/site-packages/airflow/providers/ssh/operators/ssh.py", line 168, in execute
    raise AirflowException(f"error running cmd: {self.command}, error: {error_msg}")
airflow.exceptions.AirflowException: error running cmd: echo "shit airflow, error: 

During handling of the above exception, another exception occurred:

Traceback (most recent call last):
  File "/home/ub/airflow/env/lib/python3.6/site-packages/airflow/models/taskinstance.py", line 1086, in _run_raw_task
    self._prepare_and_execute_task_with_callbacks(context, task)
  File "/home/ub/airflow/env/lib/python3.6/site-packages/airflow/models/taskinstance.py", line 1260, in _prepare_and_execute_task_with_callbacks
    result = self._execute_task(context, task_copy)
  File "/home/ub/airflow/env/lib/python3.6/site-packages/airflow/models/taskinstance.py", line 1300, in _execute_task
    result = task_copy.execute(context=context)
  File "/home/ub/airflow/env/lib/python3.6/site-packages/airflow/providers/ssh/operators/ssh.py", line 171, in execute
    raise AirflowException("SSH operator error: {}".format(str(e)))
airflow.exceptions.AirflowException: SSH operator error: error running cmd: echo "shit airflow, error: 
[2020-12-25 15:49:46,040] {taskinstance.py:1440} INFO - Marking task as FAILED. dag_id=foodpanda, task_id=t1, execution_date=20201225T074943, start_date=20201225T074945, end_date=20201225T074946
[2020-12-25 15:49:46,066] {local_task_job.py:118} INFO - Task exited with return code 1
