[2020-12-28 14:02:13,972] {taskinstance.py:826} INFO - Dependencies all met for <TaskInstance: test_slack.failure 2020-12-28T06:02:12.233267+00:00 [queued]>
[2020-12-28 14:02:13,982] {taskinstance.py:826} INFO - Dependencies all met for <TaskInstance: test_slack.failure 2020-12-28T06:02:12.233267+00:00 [queued]>
[2020-12-28 14:02:13,982] {taskinstance.py:1017} INFO - 
--------------------------------------------------------------------------------
[2020-12-28 14:02:13,982] {taskinstance.py:1018} INFO - Starting attempt 1 of 1
[2020-12-28 14:02:13,982] {taskinstance.py:1019} INFO - 
--------------------------------------------------------------------------------
[2020-12-28 14:02:13,990] {taskinstance.py:1038} INFO - Executing <Task(SlackAPIPostOperator): failure> on 2020-12-28T06:02:12.233267+00:00
[2020-12-28 14:02:13,991] {standard_task_runner.py:51} INFO - Started process 30243 to run task
[2020-12-28 14:02:13,994] {standard_task_runner.py:75} INFO - Running: ['airflow', 'tasks', 'run', 'test_slack', 'failure', '2020-12-28T06:02:12.233267+00:00', '--job-id', '15', '--pool', 'default_pool', '--raw', '--subdir', 'DAGS_FOLDER/slag_practice.py', '--cfg-path', '/tmp/tmpnuzbks6z']
[2020-12-28 14:02:13,995] {standard_task_runner.py:76} INFO - Job 15: Subtask failure
[2020-12-28 14:02:14,034] {logging_mixin.py:103} INFO - Running <TaskInstance: test_slack.failure 2020-12-28T06:02:12.233267+00:00 [running]> on host dataiku
[2020-12-28 14:02:14,075] {taskinstance.py:1232} INFO - Exporting the following env vars:
AIRFLOW_CTX_DAG_OWNER=arthur.sl.lin
AIRFLOW_CTX_DAG_ID=test_slack
AIRFLOW_CTX_TASK_ID=failure
AIRFLOW_CTX_EXECUTION_DATE=2020-12-28T06:02:12.233267+00:00
AIRFLOW_CTX_DAG_RUN_ID=manual__2020-12-28T06:02:12.233267+00:00
[2020-12-28 14:02:14,574] {taskinstance.py:1396} ERROR - The request to the Slack API failed.
The server responded with: {'ok': False, 'error': 'invalid_auth'}
Traceback (most recent call last):
  File "/home/ub/airflow/env/lib/python3.6/site-packages/airflow/models/taskinstance.py", line 1086, in _run_raw_task
    self._prepare_and_execute_task_with_callbacks(context, task)
  File "/home/ub/airflow/env/lib/python3.6/site-packages/airflow/models/taskinstance.py", line 1260, in _prepare_and_execute_task_with_callbacks
    result = self._execute_task(context, task_copy)
  File "/home/ub/airflow/env/lib/python3.6/site-packages/airflow/models/taskinstance.py", line 1300, in _execute_task
    result = task_copy.execute(context=context)
  File "/home/ub/airflow/env/lib/python3.6/site-packages/airflow/providers/slack/operators/slack.py", line 87, in execute
    slack.call(self.method, json=self.api_params)
  File "/home/ub/airflow/env/lib/python3.6/site-packages/airflow/providers/slack/hooks/slack.py", line 103, in call
    self.client.api_call(api_method, *args, **kwargs)
  File "/home/ub/airflow/env/lib/python3.6/site-packages/slack/web/base_client.py", line 150, in api_call
    return self._sync_send(api_url=api_url, req_args=req_args)
  File "/home/ub/airflow/env/lib/python3.6/site-packages/slack/web/base_client.py", line 248, in _sync_send
    additional_headers=headers,
  File "/home/ub/airflow/env/lib/python3.6/site-packages/slack/web/base_client.py", line 377, in _urllib_api_call
    use_sync_aiohttp=False,
  File "/home/ub/airflow/env/lib/python3.6/site-packages/slack/web/slack_response.py", line 194, in validate
    raise e.SlackApiError(message=msg, response=self)
slack.errors.SlackApiError: The request to the Slack API failed.
The server responded with: {'ok': False, 'error': 'invalid_auth'}
[2020-12-28 14:02:14,575] {taskinstance.py:1440} INFO - Marking task as FAILED. dag_id=test_slack, task_id=failure, execution_date=20201228T060212, start_date=20201228T060213, end_date=20201228T060214
[2020-12-28 14:02:14,607] {local_task_job.py:118} INFO - Task exited with return code 1
