[2020-12-24 18:26:45,419] {taskinstance.py:826} INFO - Dependencies all met for <TaskInstance: foodpanda.t1 2020-12-24T10:26:42.262114+00:00 [queued]>
[2020-12-24 18:26:45,422] {taskinstance.py:826} INFO - Dependencies all met for <TaskInstance: foodpanda.t1 2020-12-24T10:26:42.262114+00:00 [queued]>
[2020-12-24 18:26:45,422] {taskinstance.py:1017} INFO - 
--------------------------------------------------------------------------------
[2020-12-24 18:26:45,422] {taskinstance.py:1018} INFO - Starting attempt 1 of 1
[2020-12-24 18:26:45,422] {taskinstance.py:1019} INFO - 
--------------------------------------------------------------------------------
[2020-12-24 18:26:45,430] {taskinstance.py:1038} INFO - Executing <Task(SSHOperator): t1> on 2020-12-24T10:26:42.262114+00:00
[2020-12-24 18:26:45,431] {standard_task_runner.py:51} INFO - Started process 12517 to run task
[2020-12-24 18:26:45,434] {standard_task_runner.py:75} INFO - Running: ['airflow', 'tasks', 'run', 'foodpanda', 't1', '2020-12-24T10:26:42.262114+00:00', '--job-id', '26', '--pool', 'default_pool', '--raw', '--subdir', 'DAGS_FOLDER/foodpanda.py', '--cfg-path', '/tmp/tmp321gkc7x']
[2020-12-24 18:26:45,434] {standard_task_runner.py:76} INFO - Job 26: Subtask t1
[2020-12-24 18:26:45,451] {logging_mixin.py:103} INFO - Running <TaskInstance: foodpanda.t1 2020-12-24T10:26:42.262114+00:00 [running]> on host dataiku
[2020-12-24 18:26:45,465] {taskinstance.py:1232} INFO - Exporting the following env vars:
AIRFLOW_CTX_DAG_OWNER=arthur.sl.lin
AIRFLOW_CTX_DAG_ID=foodpanda
AIRFLOW_CTX_TASK_ID=t1
AIRFLOW_CTX_EXECUTION_DATE=2020-12-24T10:26:42.262114+00:00
AIRFLOW_CTX_DAG_RUN_ID=manual__2020-12-24T10:26:42.262114+00:00
[2020-12-24 18:26:45,465] {ssh.py:197} WARNING - Remote Identification Change is not verified. This wont protect against Man-In-The-Middle attacks
[2020-12-24 18:26:45,465] {ssh.py:202} WARNING - No Host Key Verification. This wont protect against Man-In-The-Middle attacks
[2020-12-24 18:26:45,469] {transport.py:1819} INFO - Connected (version 2.0, client OpenSSH_7.6p1)
[2020-12-24 18:26:45,480] {transport.py:1819} INFO - Authentication (password) successful!
[2020-12-24 18:26:45,480] {ssh.py:109} INFO - Running command: docker run hello-world 2>&1 | test.txt
[2020-12-24 18:26:45,592] {ssh.py:145} WARNING - bash: test.txt: command not found
[2020-12-24 18:26:46,013] {taskinstance.py:1396} ERROR - SSH operator error: error running cmd: docker run hello-world 2>&1 | test.txt, error: bash: test.txt: command not found
Traceback (most recent call last):
  File "/home/ub/airflow/env/lib/python3.6/site-packages/airflow/providers/ssh/operators/ssh.py", line 168, in execute
    raise AirflowException(f"error running cmd: {self.command}, error: {error_msg}")
airflow.exceptions.AirflowException: error running cmd: docker run hello-world 2>&1 | test.txt, error: bash: test.txt: command not found


During handling of the above exception, another exception occurred:

Traceback (most recent call last):
  File "/home/ub/airflow/env/lib/python3.6/site-packages/airflow/models/taskinstance.py", line 1086, in _run_raw_task
    self._prepare_and_execute_task_with_callbacks(context, task)
  File "/home/ub/airflow/env/lib/python3.6/site-packages/airflow/models/taskinstance.py", line 1260, in _prepare_and_execute_task_with_callbacks
    result = self._execute_task(context, task_copy)
  File "/home/ub/airflow/env/lib/python3.6/site-packages/airflow/models/taskinstance.py", line 1300, in _execute_task
    result = task_copy.execute(context=context)
  File "/home/ub/airflow/env/lib/python3.6/site-packages/airflow/providers/ssh/operators/ssh.py", line 171, in execute
    raise AirflowException("SSH operator error: {}".format(str(e)))
airflow.exceptions.AirflowException: SSH operator error: error running cmd: docker run hello-world 2>&1 | test.txt, error: bash: test.txt: command not found

[2020-12-24 18:26:46,014] {taskinstance.py:1440} INFO - Marking task as FAILED. dag_id=foodpanda, task_id=t1, execution_date=20201224T102642, start_date=20201224T102645, end_date=20201224T102646
[2020-12-24 18:26:46,047] {local_task_job.py:118} INFO - Task exited with return code 1
