[2020-12-28 13:57:11,807] {taskinstance.py:826} INFO - Dependencies all met for <TaskInstance: test_slack.failure 2020-12-28T05:57:10.179876+00:00 [queued]>
[2020-12-28 13:57:11,817] {taskinstance.py:826} INFO - Dependencies all met for <TaskInstance: test_slack.failure 2020-12-28T05:57:10.179876+00:00 [queued]>
[2020-12-28 13:57:11,817] {taskinstance.py:1017} INFO - 
--------------------------------------------------------------------------------
[2020-12-28 13:57:11,817] {taskinstance.py:1018} INFO - Starting attempt 1 of 1
[2020-12-28 13:57:11,817] {taskinstance.py:1019} INFO - 
--------------------------------------------------------------------------------
[2020-12-28 13:57:11,824] {taskinstance.py:1038} INFO - Executing <Task(SlackWebhookOperator): failure> on 2020-12-28T05:57:10.179876+00:00
[2020-12-28 13:57:11,826] {standard_task_runner.py:51} INFO - Started process 17002 to run task
[2020-12-28 13:57:11,828] {standard_task_runner.py:75} INFO - Running: ['airflow', 'tasks', 'run', 'test_slack', 'failure', '2020-12-28T05:57:10.179876+00:00', '--job-id', '12', '--pool', 'default_pool', '--raw', '--subdir', 'DAGS_FOLDER/slag_practice.py', '--cfg-path', '/tmp/tmput4wqtrq']
[2020-12-28 13:57:11,829] {standard_task_runner.py:76} INFO - Job 12: Subtask failure
[2020-12-28 13:57:11,871] {logging_mixin.py:103} INFO - Running <TaskInstance: test_slack.failure 2020-12-28T05:57:10.179876+00:00 [running]> on host dataiku
[2020-12-28 13:57:11,919] {taskinstance.py:1232} INFO - Exporting the following env vars:
AIRFLOW_CTX_DAG_OWNER=arthur.sl.lin
AIRFLOW_CTX_DAG_ID=test_slack
AIRFLOW_CTX_TASK_ID=failure
AIRFLOW_CTX_EXECUTION_DATE=2020-12-28T05:57:10.179876+00:00
AIRFLOW_CTX_DAG_RUN_ID=manual__2020-12-28T05:57:10.179876+00:00
[2020-12-28 13:57:11,991] {base.py:74} INFO - Using connection to: id: slack. Host: hooks.slack.com/services/T01D1RB1EMQ/, Port: None, Schema: , Login: , Password: None, extra: None
[2020-12-28 13:57:11,992] {http.py:140} INFO - Sending 'POST' to url: http://hooks.slack.com/services/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
[2020-12-28 13:57:12,571] {http.py:154} ERROR - HTTP error: Bad Request
[2020-12-28 13:57:12,571] {http.py:155} ERROR - invalid_payload
[2020-12-28 13:57:12,578] {taskinstance.py:1396} ERROR - 400:Bad Request
Traceback (most recent call last):
  File "/home/ub/airflow/env/lib/python3.6/site-packages/airflow/providers/http/hooks/http.py", line 152, in check_response
    response.raise_for_status()
  File "/home/ub/airflow/env/lib/python3.6/site-packages/requests/models.py", line 941, in raise_for_status
    raise HTTPError(http_error_msg, response=self)
requests.exceptions.HTTPError: 400 Client Error: Bad Request for url: https://hooks.slack.com/services/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

During handling of the above exception, another exception occurred:

Traceback (most recent call last):
  File "/home/ub/airflow/env/lib/python3.6/site-packages/airflow/models/taskinstance.py", line 1086, in _run_raw_task
    self._prepare_and_execute_task_with_callbacks(context, task)
  File "/home/ub/airflow/env/lib/python3.6/site-packages/airflow/models/taskinstance.py", line 1260, in _prepare_and_execute_task_with_callbacks
    result = self._execute_task(context, task_copy)
  File "/home/ub/airflow/env/lib/python3.6/site-packages/airflow/models/taskinstance.py", line 1300, in _execute_task
    result = task_copy.execute(context=context)
  File "/home/ub/airflow/env/lib/python3.6/site-packages/airflow/providers/slack/operators/slack_webhook.py", line 120, in execute
    self.hook.execute()
  File "/home/ub/airflow/env/lib/python3.6/site-packages/airflow/providers/slack/hooks/slack_webhook.py", line 166, in execute
    extra_options={'proxies': proxies, 'check_response': True},
  File "/home/ub/airflow/env/lib/python3.6/site-packages/airflow/providers/http/hooks/http.py", line 141, in run
    return self.run_and_check(session, prepped_request, extra_options)
  File "/home/ub/airflow/env/lib/python3.6/site-packages/airflow/providers/http/hooks/http.py", line 191, in run_and_check
    self.check_response(response)
  File "/home/ub/airflow/env/lib/python3.6/site-packages/airflow/providers/http/hooks/http.py", line 156, in check_response
    raise AirflowException(str(response.status_code) + ":" + response.reason)
airflow.exceptions.AirflowException: 400:Bad Request
[2020-12-28 13:57:12,579] {taskinstance.py:1440} INFO - Marking task as FAILED. dag_id=test_slack, task_id=failure, execution_date=20201228T055710, start_date=20201228T055711, end_date=20201228T055712
[2020-12-28 13:57:12,640] {local_task_job.py:118} INFO - Task exited with return code 1
